<sdf version='1.7'>
<model name='robot_swerve'>
<link name="base_link">
  <inertial>
    <origin xyz="-1.7560433548719815e-16 -1.1706955699146543e-16 0.16007682828480888" rpy="0 0 0"/>
    <mass value="312.2452326040869"/>
    <inertia ixx="10.489644" iyy="13.496294" izz="21.038002" ixy="-0.0" iyz="-0.0" ixz="-0.0"/>
  </inertial>
  <visual>
    <origin xyz="0 0 0" rpy="0 0 0"/>
    <geometry>
        <scale>0.001 0.001 0.001</scale>
        <uri>model://robot_swerve_description/meshes/base_link.stl</uri>
        </mesh>
    </geometry>
    <material name="silver"/>
  </visual>
  <collision>
    <origin xyz="0 0 0" rpy="0 0 0"/>
    <geometry>
      <mesh>
        <scale>0.001 0.001 0.001</scale>
        <uri>model://robot_swerve_description/meshes/base_link.stl</uri>
        </mesh>
    </geometry>
    <surface>
      <contact>
        <ode/>
      </contact>
      <friction>
        <ode>
          <mu>0.05</mu>
          <mu2>0.05</mu2>
        </ode>
      </friction>
    </surface>
  </collision>
</link>

<link name="hoder_front_left_link_1">
  <inertial>
    <origin xyz="-0.017559668837691944 -0.023585279990888608 -0.05340534668698291" rpy="0 0 0"/>
    <mass value="2.7257031571818406"/>
    <inertia ixx="0.009565" iyy="0.010271" izz="0.005039" ixy="0.000154" iyz="-0.001902" ixz="-0.001139"/>
  </inertial>
  <visual>
    <origin xyz="-0.3 -0.25 -0.15" rpy="0 0 0"/>
    <geometry>
      <mesh>
        <scale>0.001 0.001 0.001</scale>
        <uri>model://robot_swerve_description/meshes/hoder_front_left_link_1.stl</uri>
      </mesh>
    </geometry>
    <material name="silver"/>
  </visual>
  <collision>
    <origin xyz="-0.3 -0.25 -0.15" rpy="0 0 0"/>
    <geometry>
       <mesh>
        <scale>0.001 0.001 0.001</scale>
        <uri>model://robot_swerve_description/meshes/hoder_front_left_link_1.stl</uri>
      </mesh>
    </geometry>
    <surface>
      <contact>
        <ode/>
      </contact>
      <friction>
        <ode>
          <mu>0.05</mu>
          <mu2>0.05</mu2>
        </ode>
      </friction>
    </surface>
  </collision>
</link>


<link name="wheel_front_left_link_1">
  <inertial>
    <origin xyz="0.04327745021036894 0.06829795314907239 2.9363386780910383e-07" rpy="0 0 0"/>
    <mass value="7.520393550565899"/>
    <inertia ixx="0.014956" iyy="0.018705" izz="0.012445" ixy="0.003965" iyz="0.0" ixz="0.0"/>
  </inertial>
  <visual>
    <origin xyz="-0.266781 -0.19173 -0.010648" rpy="0 0 0"/>
    <geometry>
      <mesh>
        <scale>0.001 0.001 0.001</scale>
        <uri>model://robot_swerve_description/meshes/wheel_front_left_link_1.stl</uri>
      </mesh>
    </geometry>
    <material name="silver"/>
  </visual>
  <collision>
    <origin xyz="-0.266781 -0.19173 -0.010648" rpy="0 0 0"/>
       <mesh>
        <scale>0.001 0.001 0.001</scale>
        <uri>model://robot_swerve_description/meshes/wheel_front_left_link_1.stl</uri>
      </mesh>
  </collision>
</link>

<link name="hoder_front_right_link_1">
  <inertial>
    <origin xyz="0.02296089214049646 -0.018368604615615736 -0.053405333092124946" rpy="0 0 0"/>
    <mass value="2.7257045279949352"/>
    <inertia ixx="0.009686" iyy="0.010151" izz="0.005039" ixy="-0.000307" iyz="-0.001552" ixz="0.001584"/>
  </inertial>
  <visual>
    <origin xyz="-0.3 0.25 -0.15" rpy="0 0 0"/>
    <geometry>
      <mesh>
        <scale>0.001 0.001 0.001</scale>
        <uri>model://robot_swerve_description/meshes/hoder_front_right_link_1.stl</uri>
      </mesh>
    </geometry>
    <material name="silver"/>
  </visual>
  <collision>
    <origin xyz="-0.3 0.25 -0.15" rpy="0 0 0"/>
    <geometry>
       <mesh>
        <scale>0.001 0.001 0.001</scale>
        <uri>model://robot_swerve_description/meshes/hoder_front_right_link_1.stl</uri>
      </mesh>
    </geometry>
    <surface>
      <contact>
        <ode/>
      </contact>
      <friction>
        <ode>
          <mu>0.05</mu>
          <mu2>0.05</mu2>
        </ode>
      </friction>
    </surface>
  </collision>
</link>

<link name="wheel_front_right_link_1">
  <inertial>
    <origin xyz="-0.05916453480744127 0.05510890607180832 2.733302255624598e-07" rpy="0 0 0"/>
    <mass value="7.520481495384261"/>
    <inertia ixx="0.01714" iyy="0.016522" izz="0.012445" ixy="-0.004375" iyz="0.0" ixz="-0.0"/>
  </inertial>
  <visual>
    <origin xyz="-0.346894 0.297956 -0.010648" rpy="0 0 0"/>
    <geometry>
      <mesh>
        <scale>0.001 0.001 0.001</scale>
        <uri>model://robot_swerve_description/meshes/wheel_front_right_link_1.stl</uri>
      </mesh>
    </geometry>
    <material name="silver"/>
  </visual>
  <collision>
    <origin xyz="-0.346894 0.297956 -0.010648" rpy="0 0 0"/>
    <geometry>
      <mesh>
        <scale>0.001 0.001 0.001</scale>
        <uri>model://robot_swerve_description/meshes/wheel_front_right_link_1.stl</uri>
      </mesh>
    </geometry>
  </collision>
</link>

<link name="hoder_back_right_link_1">
  <inertial>
    <origin xyz="-0.01574905461727749 0.024830947012043803 -0.053405315604681036" rpy="0 0 0"/>
    <mass value="2.725705567519877"/>
    <inertia ixx="0.010079" iyy="0.009758" izz="0.005039" ixy="-0.00035" iyz="0.001744" ixz="-0.001369"/>
  </inertial>
  <visual>
    <origin xyz="0.3 0.25 -0.15" rpy="0 0 0"/>
    <geometry>
      <mesh>
        <scale>0.001 0.001 0.001</scale>
        <uri>model://robot_swerve_description/meshes/hoder_back_right_link_1.stl</uri>
      </mesh>
    </geometry>
    <material name="silver"/>
  </visual>
  <collision>
    <origin xyz="0.3 0.25 -0.15" rpy="0 0 0"/>
    <geometry>
       <mesh>
        <scale>0.001 0.001 0.001</scale>
        <uri>model://robot_swerve_description/meshes/hoder_back_right_link_1.stl</uri>
      </mesh>
    </geometry>
    <surface>
      <contact>
        <ode/>
      </contact>
      <friction>
        <ode>
          <mu>0.05</mu>
          <mu2>0.05</mu2>
        </ode>
      </friction>
    </surface>
  </collision>
</link>

<link name="wheel_back_right_link_1">
  <inertial>
    <origin xyz="0.048312363545901627 -0.0648337045413441 4.5307424978088817e-07" rpy="0 0 0"/>
    <mass value="7.520393550565899"/>
    <inertia ixx="0.015579" iyy="0.018082" izz="0.012445" ixy="-0.004203" iyz="-0.0" ixz="0.0"/>
  </inertial>
  <visual>
    <origin xyz="0.342543 0.198145 -0.010648" rpy="0 0 0"/>
    <geometry>
       <mesh>
        <scale>0.001 0.001 0.001</scale>
        <uri>model://robot_swerve_description/meshes/wheel_back_right_link_1.stl</uri>
      </mesh>
    </geometry>
    <material name="silver"/>
  </visual>
  <collision>
    <origin xyz="0.342543 0.198145 -0.010648" rpy="0 0 0"/>
    <geometry>
      <mesh>
        <scale>0.001 0.001 0.001</scale>
        <uri>model://robot_swerve_description/meshes/wheel_back_right_link_1.stl</uri>
      </mesh>
    </geometry>
  </collision>
</link>

<link name="hoder_back_left_link_1">
  <inertial>
    <origin xyz="-0.013705488924829423 -0.026014747052211074 -0.05340534460078275" rpy="0 0 0"/>
    <mass value="2.725703374914395"/>
    <inertia ixx="0.01002" iyy="0.009816" izz="0.005039" ixy="0.000371" iyz="-0.001848" ixz="-0.001225"/>
  </inertial>
  <visual>
    <origin xyz="0.3 -0.25 -0.15" rpy="0 0 0"/>
    <geometry>
      <mesh>
        <scale>0.001 0.001 0.001</scale>
        <uri>model://robot_swerve_description/meshes/hoder_back_left_link_1.stl</uri>
      </mesh>
    </geometry>
    <material name="silver"/>
  </visual>
  <collision>
    <origin xyz="0.3 -0.25 -0.15" rpy="0 0 0"/>
    <geometry>
       <mesh>
        <scale>0.001 0.001 0.001</scale>
        <uri>model://robot_swerve_description/meshes/hoder_back_left_link_1.stl</uri>
      </mesh>
    </geometry>
    <surface>
      <contact>
        <ode/>
      </contact>
      <friction>
        <ode>
          <mu>0.05</mu>
          <mu2>0.05</mu2>
        </ode>
      </friction>
    </surface>
  </collision>
</link>

<link name="wheel_back_left_link_1">
  <inertial>
    <origin xyz="0.04295275629100681 0.06850253683589722 3.807380320052997e-06" rpy="0 0 0"/>
    <mass value="7.520481495384261"/>
    <inertia ixx="0.014922" iyy="0.01874" izz="0.012445" ixy="0.003948" iyz="1e-06" ixz="1e-06"/>
  </inertial>
  <visual>
    <origin xyz="0.338245 -0.194898 -0.010648" rpy="0 0 0"/>
    <geometry>
      <mesh>
        <scale>0.001 0.001 0.001</scale>
        <uri>model://robot_swerve_description/meshes/wheel_back_left_link_1.stl</uri>
      </mesh>
    </geometry>
    <material name="silver"/>
  </visual>
  <collision>
    <origin xyz="0.338245 -0.194898 -0.010648" rpy="0 0 0"/>
    <geometry>
      <mesh>
        <scale>0.001 0.001 0.001</scale>
        <uri>model://robot_swerve_description/meshes/wheel_back_left_link_1.stl</uri>
      </mesh>
    </geometry>
  </collision>
</link>

<joint name="hoder_front_left_joint" type="continuous">
  <origin xyz="0.3 0.25 0.15" rpy="0 0 0"/>
  <parent link="base_link"/>
  <child link="hoder_front_left_link_1"/>
  <axis>
    <xyz>0.0 0.0 -1.0</xyz>
    <limit>
      <lower>-2.1</lower>
      <upper>2.1</upper>
      <effort>5</effort>
      <velocity>6.28</velocity>
    </limit>
    <dynamics>
      <damping>0.005</damping>
      <friction>0.02</friction>
      <spring_reference>0</spring_reference>
      <spring_stiffness>0</spring_stiffness>
    </dynamics>
  </axis>
</joint>

<joint name="wheel_front_left_joint" type="continuous">
  <origin xyz="-0.033219 -0.05827 -0.139352" rpy="0 0 0"/>
  <parent link="hoder_front_left_link_1"/>
  <child link="wheel_front_left_link_1"/>
  <axis>
    <xyz>0.535323 0.844648 -0.0</xyz>
    <limit>
      <effort>1.5</effort>
      <velocity>20</velocity>
      <lower>-1e+16</lower>
      <upper>1e+16</upper>
    </limit>
    <dynamics>
      <damping>0.005</damping>
      <friction>0.02</friction>
      <spring_reference>0</spring_reference>
      <spring_stiffness>0</spring_stiffness>
    </dynamics>
  </axis>
</joint>

<joint name="hoder_front_right_joint" type="continuous">
  <origin xyz="0.3 -0.25 0.15" rpy="0 0 0"/>
  <parent link="base_link"/>
  <child link="hoder_front_right_link_1"/>
  <axis>
    <xyz>0.0 0.0 -1.0</xyz>
    <limit>
      <lower>-2.1</lower>
      <upper>2.1</upper>
      <effort>5</effort>
      <velocity>6.28</velocity>
    </limit>
    <dynamics>
      <damping>0.005</damping>
      <friction>0.02</friction>
      <spring_reference>0</spring_reference>
      <spring_stiffness>0</spring_stiffness>
    </dynamics>
  </axis>
</joint>

<joint name="wheel_front_right_joint" type="continuous">
  <origin xyz="0.046894 -0.047956 -0.139352" rpy="0 0 0"/>
  <parent link="hoder_front_right_link_1"/>
  <child link="wheel_front_right_link_1"/>
  <axis>
    <xyz>0.731803 -0.681516 0.0</xyz>
    <limit>
      <effort>1.5</effort>
      <velocity>20</velocity>
      <lower>-1e+16</lower>
      <upper>1e+16</upper>
    </limit>
    <dynamics>
      <damping>0.005</damping>
      <friction>0.02</friction>
      <spring_reference>0</spring_reference>
      <spring_stiffness>0</spring_stiffness>
    </dynamics>
  </axis>
</joint>

<joint name="hoder_back_right_joint" type="continuous">
  <origin xyz="-0.3 -0.25 0.15" rpy="0 0 0"/>
  <parent link="base_link"/>
  <child link="hoder_back_right_link_1"/>
  <axis>
    <xyz>0.0 0.0 -1.0</xyz>
    <limit>
      <lower>-2.1</lower>
      <upper>2.1</upper>
      <effort>5</effort>
      <velocity>6.28</velocity>
    </limit>
    <dynamics>
      <damping>0.005</damping>
      <friction>0.02</friction>
      <spring_reference>0</spring_reference>
      <spring_stiffness>0</spring_stiffness>
    </dynamics>
  </axis>
</joint>

<joint name="wheel_back_right_joint" type="continuous">
  <origin xyz="-0.042543 0.051855 -0.139352" rpy="0 0 0"/>
  <parent link="hoder_back_right_link_1"/>
  <child link="wheel_back_right_link_1"/>
  <axis>
    <xyz>-0.597452 0.801905 0.0</xyz>
    <limit>
      <effort>1.5</effort>
      <velocity>20</velocity>
      <lower>-1e+16</lower>
      <upper>1e+16</upper>
    </limit>
    <dynamics>
      <damping>0.005</damping>
      <friction>0.02</friction>
      <spring_reference>0</spring_reference>
      <spring_stiffness>0</spring_stiffness>
    </dynamics>
  </axis>
</joint>

<joint name="hoder_back_left_joint" type="continuous">
  <origin xyz="-0.3 0.25 0.15" rpy="0 0 0"/>
  <parent link="base_link"/>
  <child link="hoder_back_left_link_1"/>
  <axis>
    <xyz>0.0 0.0 -1.0</xyz>
    <limit>
      <lower>-2.1</lower>
      <upper>2.1</upper>
      <effort>5</effort>
      <velocity>6.28</velocity>
    </limit>
    <dynamics>
      <damping>0.005</damping>
      <friction>0.02</friction>
      <spring_reference>0</spring_reference>
      <spring_stiffness>0</spring_stiffness>
    </dynamics>
  </axis>
</joint>

<joint name="wheel_back_left_joint" type="continuous">
  <origin xyz="-0.038245 -0.055102 -0.139352" rpy="0 0 0"/>
  <parent link="hoder_back_left_link_1"/>
  <child link="wheel_back_left_link_1"/>
  <axis>
    <xyz>-0.531168 -0.847267 0.0</xyz>
    <limit>
      <effort>1.5</effort>
      <velocity>20</velocity>
      <lower>-1e+16</lower>
      <upper>1e+16</upper>
    </limit>
    <dynamics>
      <damping>0.005</damping>
      <friction>0.02</friction>
      <spring_reference>0</spring_reference>
      <spring_stiffness>0</spring_stiffness>
    </dynamics>
  </axis>
</joint>

    <static>0</static>

    <plugin name="four_ws_robot_joint_state" filename="libgazebo_ros_joint_state_publisher.so">
      <ros>
          <remapping>~/out:=joint_states</remapping>
      </ros>
      <update_rate>30</update_rate>
      <joint_name>wheel_front_left_joint</joint_name>
      <joint_name>wheel_front_right_joint</joint_name>
      <joint_name>wheel_back_left_joint</joint_name>
      <joint_name>wheel_back_right_joint</joint_name>
      <joint_name>hoder_front_left_joint</joint_name>
      <joint_name>hoder_front_right_joint</joint_name>
      <joint_name>hoder_back_left_joint</joint_name>
      <joint_name>hoder_back_right_joint</joint_name>
    </plugin>


  <ros2_control name="GazeboSystem" type="system">
    <hardware>
      <plugin>gazebo_ros2_control/GazeboSystem</plugin>
    </hardware>
    
    <joint name="wheel_front_left_joint">
      <command_interface name="velocity">
        <param name="min">-3.14</param>
        <param name="max">3.14</param>
      </command_interface>
      <state_interface name="velocity"/>
      <state_interface name="effort"/>
    </joint>

    <joint name="wheel_front_right_joint">
      <command_interface name="velocity">
        <param name="min">-3.14</param>
        <param name="max">3.14</param>
      </command_interface>
      <state_interface name="velocity"/>
      <state_interface name="effort"/>
    </joint>

    <joint name="wheel_back_left_joint">
      <command_interface name="velocity">
        <param name="min">-3.14</param>
        <param name="max">3.14</param>
      </command_interface>
      <state_interface name="velocity"/>
      <state_interface name="effort"/>
    </joint>

    <joint name="wheel_back_right_joint">
      <command_interface name="velocity">
        <param name="min">-3.14</param>
        <param name="max">3.14</param>
      </command_interface>
      <state_interface name="velocity"/>
      <state_interface name="effort"/>
    </joint>

    <joint name="hoder_front_left_joint">
      <command_interface name="position">
        <param name="min">-3.14</param>
        <param name="max">3.14</param>
      </command_interface>
      <state_interface name="position"/>
      <state_interface name="velocity"/>
      <state_interface name="effort"/>
    </joint>

    <joint name="hoder_front_right_joint">
      <command_interface name="position">
        <param name="min">-3.14</param>
        <param name="max">3.14</param>
      </command_interface>
      <state_interface name="position"/>
      <state_interface name="velocity"/>
      <state_interface name="effort"/>
    </joint>

    <joint name="hoder_back_left_joint">
      <command_interface name="position">
        <param name="min">-3.14</param>
        <param name="max">3.14</param>
      </command_interface>
      <state_interface name="position"/>
      <state_interface name="velocity"/>
      <state_interface name="effort"/>
    </joint>

    <joint name="hoder_back_right_joint">
      <command_interface name="position">
        <param name="min">-3.14</param>
        <param name="max">3.14</param>
      </command_interface>
      <state_interface name="position"/>
      <state_interface name="velocity"/>
      <state_interface name="effort"/>
    </joint>
  </ros2_control>

    <plugin name="gazebo_ros2_control" filename="libgazebo_ros2_control.so">
      <parameters>/home/nitro110/ROS2/swerve_ws/install/robot_swerve_description/share/robot_swerve_description/models/robot_swerve_description/config/controllers.yaml</parameters>
    </plugin>

  </model>
</sdf>
